<?xml version="1.0"?>
<robot name="robot_arm">
    <link name="base">
        <visual>
            <origin xyz="0 0 -0.015" rpy="0 0 0"/>
            <geometry>
                <cylinder radius="0.04" length="0.03"/>
            </geometry>
        </visual>
        <collision>
            <origin xyz="0 0 -0.015" rpy="0 0 0"/>
            <geometry>
                <cylinder radius="0.04" length="0.03"/>
            </geometry>
        </collision>
    </link>
    <link name="upper_arm">
        <visual>
            <origin xyz="0 0 0" rpy="0 0 0"/>
            <geometry>
                <mesh filename="package://robot_arm_description/models/upper_arm.stl"/>
            </geometry>
        </visual>
        <collision>
            <origin xyz="0 0 0" rpy="0 0 0"/>
            <geometry>
                <mesh filename="package://robot_arm_description/models/upper_arm.stl"/>
            </geometry>
        </collision>
    </link>
    <link name="arm">
        <visual>
            <origin xyz="0 0 0" rpy="0 0 0"/>
            <geometry>
                <mesh filename="package://robot_arm_description/models/arm.stl"/>
            </geometry>
        </visual>
        <collision>
            <origin xyz="0 0 0" rpy="0 0 0"/>
            <geometry>
                <mesh filename="package://robot_arm_description/models/arm.stl"/>
            </geometry>
        </collision>
    </link>
    <link name="forearm">
        <visual>
            <origin xyz="0 0.001 0" rpy="0 0 0"/>
            <geometry>
                <mesh filename="package://robot_arm_description/models/forearm.stl"/>
            </geometry>
        </visual>
        <collision>
            <origin xyz="0 0.001 0" rpy="0 0 0"/>
            <geometry>
                <mesh filename="package://robot_arm_description/models/forearm.stl"/>
            </geometry>
        </collision>
    </link>
    <link name="hand">
        <visual>
            <origin xyz="0 0 0" rpy="0 0 0"/>
            <geometry>
                <mesh filename="package://robot_arm_description/models/hand.stl"/>
            </geometry>
        </visual>
        <collision>
            <origin xyz="0 0 0" rpy="0 0 0"/>
            <geometry>
                <mesh filename="package://robot_arm_description/models/hand.stl"/>
            </geometry>
        </collision>
    </link>
    <link name="carpals">
        <visual>
            <origin xyz="0 0 0" rpy="0 0 0"/>
            <geometry>
                <mesh filename="package://robot_arm_description/models/carpals.stl"/>
            </geometry>
        </visual>
        <collision>
            <origin xyz="0 0 0" rpy="0 0 0"/>
            <geometry>
                <mesh filename="package://robot_arm_description/models/carpals.stl"/>
            </geometry>
        </collision>
    </link>
    <link name="left_finger">
        <visual>
            <origin xyz="0 0 0" rpy="0 0 0"/>
            <geometry>
                <mesh filename="package://robot_arm_description/models/finger.stl"/>
            </geometry>
        </visual>
        <collision>
            <origin xyz="0 0 0" rpy="0 0 0"/>
            <geometry>
                <mesh filename="package://robot_arm_description/models/finger.stl"/>
            </geometry>
        </collision>
    </link>
    <link name="right_finger">
        <visual>
            <origin xyz="0 0 0" rpy="0 0 3.1415"/>
            <geometry>
                <mesh filename="package://robot_arm_description/models/finger.stl"/>
            </geometry>
        </visual>
        <collision>
            <origin xyz="0 0 0" rpy="0 0 3.1415"/>
            <geometry>
                <mesh filename="package://robot_arm_description/models/finger.stl"/>
            </geometry>
        </collision>
    </link>
    <link name="tcp_link"/>
    <joint name="shoulder_psi" type="continuous">
        <parent link="base"/>
        <child link="upper_arm"/>
        <origin xyz="0 0 0"/>
        <axis xyz = "0 0 1"/>
    </joint>
    <joint name="shoulder_theta" type="continuous">
        <parent link="upper_arm"/>
        <child link="arm"/>
        <origin xyz="0 0 0.014195"/>
        <axis xyz = "0 1 0"/>
    </joint>
    <joint name="elbow" type="continuous">
        <parent link="arm"/>
        <child link="forearm"/>
        <origin xyz="0 0 0.0912"/>
        <axis xyz = "0 -1 0"/>
    </joint>
    <joint name="wrist_theta" type="continuous">
        <parent link="forearm"/>
        <child link="hand"/>
        <origin xyz="0 0 0.08698"/>
        <axis xyz = "0 1 0"/>
    </joint>
    <joint name="wrist_psi" type="continuous">
        <parent link="hand"/>
        <child link="carpals"/>
        <origin xyz="-0.0284 -0.013296 0.041274"/>
        <axis xyz = "0 0 1"/>
    </joint>
    <joint name="tcp_joint" type="fixed">
        <parent link="carpals"/>
        <child link="tcp_link"/>
        <origin xyz="0 0 0.06"/>
        <axis xyz = "0 0 1"/>
    </joint>
    <joint name="left_knuckle" type="prismatic">
        <limit lower="0" upper="0.03" velocity="1" effort="1"/>
        <parent link="carpals"/>
        <child link="left_finger"/>
        <origin xyz="0 0 0.031"/>
        <axis xyz = "0 -1 0"/>
    </joint>
    <joint name="right_knuckle" type="prismatic">
        <limit lower="0" upper="0.03" velocity="1" effort="1"/>
        <mimic joint="left_knuckle"/>
        <parent link="carpals"/>
        <child link="right_finger"/>
        <origin xyz="0 0 0.031"/>
        <axis xyz = "0 1 0"/>
    </joint>
</robot>
